2025-02-16T22:16:08 {"block_run_id": 70, "block_uuid": "lecturadatos", "pipeline_run_id": 24, "pipeline_schedule_id": 1, "pipeline_uuid": "descuento", "hostname": "d79e8dc5d15d", "block_type": "data_loader", "level": "INFO", "message": "Start executing block with BlockExecutor.", "timestamp": 1739744168.722158, "uuid": "6ea685c77df342bb91a96e874b6dab49"}
2025-02-16T22:16:08 {"block_run_id": 70, "block_uuid": "lecturadatos", "pipeline_run_id": 24, "pipeline_schedule_id": 1, "pipeline_uuid": "descuento", "hostname": "d79e8dc5d15d", "block_type": "data_loader", "level": "INFO", "message": "Postgres initialized", "timestamp": 1739744168.800819, "uuid": "3d6a6aca97a441df9725f14e749f46a0"}
2025-02-16T22:16:08 {"block_run_id": 70, "block_uuid": "lecturadatos", "pipeline_run_id": 24, "pipeline_schedule_id": 1, "pipeline_uuid": "descuento", "hostname": "d79e8dc5d15d", "block_type": "data_loader", "level": "INFO", "message": "\u2514\u2500 Opening connection to PostgreSQL database...", "timestamp": 1739744168.801149, "uuid": "4ffac6b9c2904b0099a88f1849215953"}
2025-02-16T22:16:10 {"block_run_id": 70, "block_uuid": "lecturadatos", "pipeline_run_id": 24, "pipeline_schedule_id": 1, "pipeline_uuid": "descuento", "hostname": "d79e8dc5d15d", "block_type": "data_loader", "level": "INFO", "message": "Traceback (most recent call last):", "timestamp": 1739744170.880151, "uuid": "786e6c36d9e1437ab456c8ecfa03da5a"}
2025-02-16T22:16:10 {"block_run_id": 70, "block_uuid": "lecturadatos", "pipeline_run_id": 24, "pipeline_schedule_id": 1, "pipeline_uuid": "descuento", "hostname": "d79e8dc5d15d", "block_type": "data_loader", "level": "INFO", "message": "  File \"/usr/local/lib/python3.10/site-packages/mage_ai/io/postgres.py\", line 163, in open", "timestamp": 1739744170.880722, "uuid": "3e4dae06c4574796ac208b11466c7980"}
2025-02-16T22:16:10 {"block_run_id": 70, "block_uuid": "lecturadatos", "pipeline_run_id": 24, "pipeline_schedule_id": 1, "pipeline_uuid": "descuento", "hostname": "d79e8dc5d15d", "block_type": "data_loader", "level": "INFO", "message": "    self._ctx = connect(**connect_opts)", "timestamp": 1739744170.881178, "uuid": "040ab1256c204367856e313ffccb23d7"}
2025-02-16T22:16:10 {"block_run_id": 70, "block_uuid": "lecturadatos", "pipeline_run_id": 24, "pipeline_schedule_id": 1, "pipeline_uuid": "descuento", "hostname": "d79e8dc5d15d", "block_type": "data_loader", "level": "INFO", "message": "  File \"/usr/local/lib/python3.10/site-packages/psycopg2/__init__.py\", line 122, in connect", "timestamp": 1739744170.881493, "uuid": "c84bf187344348e9944c38cb659075a3"}
2025-02-16T22:16:10 {"block_run_id": 70, "block_uuid": "lecturadatos", "pipeline_run_id": 24, "pipeline_schedule_id": 1, "pipeline_uuid": "descuento", "hostname": "d79e8dc5d15d", "block_type": "data_loader", "level": "INFO", "message": "    conn = _connect(dsn, connection_factory=connection_factory, **kwasync)", "timestamp": 1739744170.881791, "uuid": "a48f20c6edcf4f1ba2be4a2497751010"}
2025-02-16T22:16:10 {"block_run_id": 70, "block_uuid": "lecturadatos", "pipeline_run_id": 24, "pipeline_schedule_id": 1, "pipeline_uuid": "descuento", "hostname": "d79e8dc5d15d", "block_type": "data_loader", "level": "INFO", "message": "psycopg2.OperationalError: could not translate host name \"postgres\" to address: Name or service not known", "timestamp": 1739744170.882091, "uuid": "6c561a6b3f6d45dcbc329edb298a7c6d"}
2025-02-16T22:16:10 {"block_run_id": 70, "block_uuid": "lecturadatos", "pipeline_run_id": 24, "pipeline_schedule_id": 1, "pipeline_uuid": "descuento", "hostname": "d79e8dc5d15d", "block_type": "data_loader", "level": "INFO", "message": "DONE", "timestamp": 1739744170.882448, "uuid": "c05b836e82f342b88207652e3c21e5c1"}
2025-02-16T22:16:10 {"block_run_id": 70, "block_uuid": "lecturadatos", "pipeline_run_id": 24, "pipeline_schedule_id": 1, "pipeline_uuid": "descuento", "hostname": "d79e8dc5d15d", "block_type": "data_loader", "level": "INFO", "message": "", "timestamp": 1739744170.882821, "uuid": "1b5dabcd9f7a46abbf5ae24abedaf441"}
2025-02-16T22:16:10 {"block_run_id": 70, "block_uuid": "lecturadatos", "pipeline_run_id": 24, "pipeline_schedule_id": 1, "pipeline_uuid": "descuento", "hostname": "d79e8dc5d15d", "block_type": "data_loader", "level": "INFO", "message": "\u251c\u2500", "timestamp": 1739744170.883043, "uuid": "648cc7c6fc6e4f439122129fcd818eac"}
2025-02-16T22:16:10 {"block_run_id": 70, "block_uuid": "lecturadatos", "pipeline_run_id": 24, "pipeline_schedule_id": 1, "pipeline_uuid": "descuento", "hostname": "d79e8dc5d15d", "block_type": "data_loader", "level": "INFO", "message": "\u2514\u2500 Loading data with query", "timestamp": 1739744170.883285, "uuid": "cf9e8c3471084ffc8d4aed185d6d4c6c"}
2025-02-16T22:16:10 {"block_run_id": 70, "block_uuid": "lecturadatos", "pipeline_run_id": 24, "pipeline_schedule_id": 1, "pipeline_uuid": "descuento", "hostname": "d79e8dc5d15d", "block_type": "data_loader", "level": "INFO", "message": "", "timestamp": 1739744170.883467, "uuid": "1b5760a03e5e403cb085e2a5dfca3089"}
2025-02-16T22:16:10 {"block_run_id": 70, "block_uuid": "lecturadatos", "pipeline_run_id": 24, "pipeline_schedule_id": 1, "pipeline_uuid": "descuento", "hostname": "d79e8dc5d15d", "block_type": "data_loader", "level": "INFO", "message": "SELECT * FROM productos", "timestamp": 1739744170.883653, "uuid": "4752aa79d74a49b6a56d54aa39d63a3f"}
2025-02-16T22:16:10 {"block_run_id": 70, "block_uuid": "lecturadatos", "pipeline_run_id": 24, "pipeline_schedule_id": 1, "pipeline_uuid": "descuento", "hostname": "d79e8dc5d15d", "block_type": "data_loader", "level": "INFO", "message": "", "timestamp": 1739744170.883914, "uuid": "a9e61102f7514f78a86966ce3834dfd5"}
2025-02-16T22:16:10 {"block_run_id": 70, "block_uuid": "lecturadatos", "pipeline_run_id": 24, "pipeline_schedule_id": 1, "pipeline_uuid": "descuento", "hostname": "d79e8dc5d15d", "block_type": "data_loader", "level": "INFO", "message": "...", "timestamp": 1739744170.884133, "uuid": "880a34f286e9407398f8b4630458f562"}
2025-02-16T22:16:10 {"block_run_id": 70, "block_uuid": "lecturadatos", "pipeline_run_id": 24, "pipeline_schedule_id": 1, "pipeline_uuid": "descuento", "hostname": "d79e8dc5d15d", "block_type": "data_loader", "level": "WARNING", "message": "Exception thrown when attempting to run <function BlockExecutor.execute.<locals>.__execute_with_retry at 0x7ffacec4dab0>, attempt 1 of 1", "timestamp": 1739744170.884791, "uuid": "9b9affdf52fa40afa495183e48784d4b", "error": "Traceback (most recent call last):\n  File \"/usr/local/lib/python3.10/site-packages/mage_ai/io/base.py\", line 403, in conn\n    return self._ctx\nAttributeError: 'Postgres' object has no attribute '_ctx'\n\nDuring handling of the above exception, another exception occurred:\n\nTraceback (most recent call last):\n  File \"/usr/local/lib/python3.10/site-packages/mage_ai/shared/retry.py\", line 38, in retry_func\n    return func(*args, **kwargs)\n  File \"/usr/local/lib/python3.10/site-packages/mage_ai/data_preparation/executors/block_executor.py\", line 621, in __execute_with_retry\n    return self._execute(\n  File \"/usr/local/lib/python3.10/site-packages/mage_ai/data_preparation/executors/block_executor.py\", line 1154, in _execute\n    result = self.block.execute_sync(\n  File \"/usr/local/lib/python3.10/site-packages/mage_ai/data_preparation/models/block/__init__.py\", line 1691, in execute_sync\n    return __execute()\n  File \"/usr/local/lib/python3.10/site-packages/mage_ai/data_preparation/models/block/__init__.py\", line 1668, in __execute\n    raise err\n  File \"/usr/local/lib/python3.10/site-packages/mage_ai/data_preparation/models/block/__init__.py\", line 1570, in __execute\n    output = self.execute_block(\n  File \"/usr/local/lib/python3.10/site-packages/mage_ai/data_preparation/models/block/__init__.py\", line 1910, in execute_block\n    outputs = self._execute_block(\n  File \"/usr/local/lib/python3.10/site-packages/mage_ai/data_preparation/models/block/__init__.py\", line 2073, in _execute_block\n    outputs = self.execute_block_function(\n  File \"/usr/local/lib/python3.10/site-packages/mage_ai/data_preparation/models/block/__init__.py\", line 2169, in execute_block_function\n    output = block_function_updated(*input_vars, **global_vars)\n  File \"<string>\", line 24, in load_data_from_postgres\n  File \"/usr/local/lib/python3.10/site-packages/mage_ai/io/sql.py\", line 216, in load\n    self.conn,\n  File \"/usr/local/lib/python3.10/site-packages/mage_ai/io/base.py\", line 405, in conn\n    raise ConnectionError(\nConnectionError: No connection currently open. Open a new connection to access this property.\n", "error_stack": ["  File \"/usr/local/bin/mage\", line 8, in <module>\n    sys.exit(app())\n", "  File \"/usr/local/lib/python3.10/site-packages/typer/main.py\", line 311, in __call__\n    return get_command(self)(*args, **kwargs)\n", "  File \"/usr/local/lib/python3.10/site-packages/click/core.py\", line 1161, in __call__\n    return self.main(*args, **kwargs)\n", "  File \"/usr/local/lib/python3.10/site-packages/typer/core.py\", line 778, in main\n    return _main(\n", "  File \"/usr/local/lib/python3.10/site-packages/typer/core.py\", line 216, in _main\n    rv = self.invoke(ctx)\n", "  File \"/usr/local/lib/python3.10/site-packages/click/core.py\", line 1697, in invoke\n    return _process_result(sub_ctx.command.invoke(sub_ctx))\n", "  File \"/usr/local/lib/python3.10/site-packages/click/core.py\", line 1443, in invoke\n    return ctx.invoke(self.callback, **ctx.params)\n", "  File \"/usr/local/lib/python3.10/site-packages/click/core.py\", line 788, in invoke\n    return __callback(*args, **kwargs)\n", "  File \"/usr/local/lib/python3.10/site-packages/typer/main.py\", line 683, in wrapper\n    return callback(**use_params)  # type: ignore\n", "  File \"/usr/local/lib/python3.10/site-packages/mage_ai/cli/main.py\", line 147, in start\n    start_server(\n", "  File \"/usr/local/lib/python3.10/site-packages/mage_ai/server/server.py\", line 809, in start_server\n    scheduler_manager.start_scheduler()\n", "  File \"/usr/local/lib/python3.10/site-packages/mage_ai/server/scheduler_manager.py\", line 106, in start_scheduler\n    proc.start()\n", "  File \"/usr/local/lib/python3.10/multiprocessing/process.py\", line 121, in start\n    self._popen = self._Popen(self)\n", "  File \"/usr/local/lib/python3.10/multiprocessing/context.py\", line 224, in _Popen\n    return _default_context.get_context().Process._Popen(process_obj)\n", "  File \"/usr/local/lib/python3.10/multiprocessing/context.py\", line 281, in _Popen\n    return Popen(process_obj)\n", "  File \"/usr/local/lib/python3.10/multiprocessing/popen_fork.py\", line 19, in __init__\n    self._launch(process_obj)\n", "  File \"/usr/local/lib/python3.10/multiprocessing/popen_fork.py\", line 71, in _launch\n    code = process_obj._bootstrap(parent_sentinel=child_r)\n", "  File \"/usr/local/lib/python3.10/multiprocessing/process.py\", line 314, in _bootstrap\n    self.run()\n", "  File \"/usr/local/lib/python3.10/multiprocessing/process.py\", line 108, in run\n    self._target(*self._args, **self._kwargs)\n", "  File \"/usr/local/lib/python3.10/site-packages/mage_ai/orchestration/db/process.py\", line 15, in start_session_and_run\n    results = target(*args)\n", "  File \"/usr/local/lib/python3.10/site-packages/mage_ai/server/scheduler_manager.py\", line 58, in run_scheduler\n    LoopTimeTrigger().start()\n", "  File \"/usr/local/lib/python3.10/site-packages/mage_ai/orchestration/triggers/loop_time_trigger.py\", line 14, in start\n    self.run()\n", "  File \"/usr/local/lib/python3.10/site-packages/mage_ai/orchestration/triggers/time_trigger.py\", line 11, in run\n    schedule_all()\n", "  File \"/usr/local/lib/python3.10/site-packages/mage_ai/orchestration/pipeline_scheduler_original.py\", line 1702, in schedule_all\n    PipelineScheduler(r).start()\n", "  File \"/usr/local/lib/python3.10/site-packages/mage_ai/orchestration/db/__init__.py\", line 159, in func_with_rollback\n    return func(*args, **kwargs)\n", "  File \"/usr/local/lib/python3.10/site-packages/mage_ai/orchestration/pipeline_scheduler_original.py\", line 197, in start\n    self.schedule()\n", "  File \"/usr/local/lib/python3.10/site-packages/mage_ai/orchestration/db/__init__.py\", line 159, in func_with_rollback\n    return func(*args, **kwargs)\n", "  File \"/usr/local/lib/python3.10/site-packages/mage_ai/orchestration/pipeline_scheduler_original.py\", line 333, in schedule\n    self.__schedule_blocks(block_runs)\n", "  File \"/usr/local/lib/python3.10/site-packages/mage_ai/orchestration/pipeline_scheduler_original.py\", line 640, in __schedule_blocks\n    job_manager.add_job(\n", "  File \"/usr/local/lib/python3.10/site-packages/mage_ai/orchestration/job_manager.py\", line 20, in add_job\n    self.queue.enqueue(job_id, target, *args, **kwargs)\n", "  File \"/usr/local/lib/python3.10/site-packages/mage_ai/orchestration/queue/process_queue.py\", line 121, in enqueue\n    self.start_worker_pool()\n", "  File \"/usr/local/lib/python3.10/site-packages/mage_ai/orchestration/queue/process_queue.py\", line 198, in start_worker_pool\n    self.worker_pool_proc.start()\n", "  File \"/usr/local/lib/python3.10/multiprocessing/process.py\", line 121, in start\n    self._popen = self._Popen(self)\n", "  File \"/usr/local/lib/python3.10/multiprocessing/context.py\", line 224, in _Popen\n    return _default_context.get_context().Process._Popen(process_obj)\n", "  File \"/usr/local/lib/python3.10/multiprocessing/context.py\", line 281, in _Popen\n    return Popen(process_obj)\n", "  File \"/usr/local/lib/python3.10/multiprocessing/popen_fork.py\", line 19, in __init__\n    self._launch(process_obj)\n", "  File \"/usr/local/lib/python3.10/multiprocessing/popen_fork.py\", line 71, in _launch\n    code = process_obj._bootstrap(parent_sentinel=child_r)\n", "  File \"/usr/local/lib/python3.10/multiprocessing/process.py\", line 314, in _bootstrap\n    self.run()\n", "  File \"/usr/local/lib/python3.10/multiprocessing/process.py\", line 108, in run\n    self._target(*self._args, **self._kwargs)\n", "  File \"/usr/local/lib/python3.10/site-packages/mage_ai/orchestration/queue/process_queue.py\", line 351, in poll_job_and_execute\n    worker.start()\n", "  File \"/usr/local/lib/python3.10/multiprocessing/process.py\", line 121, in start\n    self._popen = self._Popen(self)\n", "  File \"/usr/local/lib/python3.10/multiprocessing/context.py\", line 224, in _Popen\n    return _default_context.get_context().Process._Popen(process_obj)\n", "  File \"/usr/local/lib/python3.10/multiprocessing/context.py\", line 281, in _Popen\n    return Popen(process_obj)\n", "  File \"/usr/local/lib/python3.10/multiprocessing/popen_fork.py\", line 19, in __init__\n    self._launch(process_obj)\n", "  File \"/usr/local/lib/python3.10/multiprocessing/popen_fork.py\", line 71, in _launch\n    code = process_obj._bootstrap(parent_sentinel=child_r)\n", "  File \"/usr/local/lib/python3.10/multiprocessing/process.py\", line 314, in _bootstrap\n    self.run()\n", "  File \"/usr/local/lib/python3.10/site-packages/newrelic/api/background_task.py\", line 117, in wrapper\n    return wrapped(*args, **kwargs)\n", "  File \"/usr/local/lib/python3.10/site-packages/mage_ai/orchestration/queue/process_queue.py\", line 315, in run\n    start_session_and_run(args[1], *args[2], **args[3])\n", "  File \"/usr/local/lib/python3.10/site-packages/mage_ai/orchestration/db/process.py\", line 15, in start_session_and_run\n    results = target(*args)\n", "  File \"/usr/local/lib/python3.10/site-packages/mage_ai/orchestration/pipeline_scheduler_original.py\", line 1235, in run_block\n    return ExecutorFactory.get_block_executor(\n", "  File \"/usr/local/lib/python3.10/site-packages/mage_ai/data_preparation/executors/block_executor.py\", line 647, in execute\n    result = __execute_with_retry()\n", "  File \"/usr/local/lib/python3.10/site-packages/mage_ai/shared/retry.py\", line 46, in retry_func\n    logger.warning(\n", "  File \"/usr/local/lib/python3.10/site-packages/mage_ai/data_preparation/logging/logger.py\", line 39, in warning\n    self.__send_message('warning', message, **kwargs)\n", "  File \"/usr/local/lib/python3.10/site-packages/mage_ai/data_preparation/logging/logger.py\", line 65, in __send_message\n    data['error_stack'] = traceback.format_stack()\n"], "error_stacktrace": "No connection currently open. Open a new connection to access this property."}
2025-02-16T22:16:10 {"block_run_id": 70, "block_uuid": "lecturadatos", "pipeline_run_id": 24, "pipeline_schedule_id": 1, "pipeline_uuid": "descuento", "hostname": "d79e8dc5d15d", "block_type": "data_loader", "level": "EXCEPTION", "message": "Failed to execute block lecturadatos", "timestamp": 1739744170.889936, "uuid": "c4fb14213c1e414e8df6a19c641fa1c9", "error": "Traceback (most recent call last):\n  File \"/usr/local/lib/python3.10/site-packages/mage_ai/io/base.py\", line 403, in conn\n    return self._ctx\nAttributeError: 'Postgres' object has no attribute '_ctx'\n\nDuring handling of the above exception, another exception occurred:\n\nTraceback (most recent call last):\n  File \"/usr/local/lib/python3.10/site-packages/mage_ai/data_preparation/executors/block_executor.py\", line 647, in execute\n    result = __execute_with_retry()\n  File \"/usr/local/lib/python3.10/site-packages/mage_ai/shared/retry.py\", line 54, in retry_func\n    raise e\n  File \"/usr/local/lib/python3.10/site-packages/mage_ai/shared/retry.py\", line 38, in retry_func\n    return func(*args, **kwargs)\n  File \"/usr/local/lib/python3.10/site-packages/mage_ai/data_preparation/executors/block_executor.py\", line 621, in __execute_with_retry\n    return self._execute(\n  File \"/usr/local/lib/python3.10/site-packages/mage_ai/data_preparation/executors/block_executor.py\", line 1154, in _execute\n    result = self.block.execute_sync(\n  File \"/usr/local/lib/python3.10/site-packages/mage_ai/data_preparation/models/block/__init__.py\", line 1691, in execute_sync\n    return __execute()\n  File \"/usr/local/lib/python3.10/site-packages/mage_ai/data_preparation/models/block/__init__.py\", line 1668, in __execute\n    raise err\n  File \"/usr/local/lib/python3.10/site-packages/mage_ai/data_preparation/models/block/__init__.py\", line 1570, in __execute\n    output = self.execute_block(\n  File \"/usr/local/lib/python3.10/site-packages/mage_ai/data_preparation/models/block/__init__.py\", line 1910, in execute_block\n    outputs = self._execute_block(\n  File \"/usr/local/lib/python3.10/site-packages/mage_ai/data_preparation/models/block/__init__.py\", line 2073, in _execute_block\n    outputs = self.execute_block_function(\n  File \"/usr/local/lib/python3.10/site-packages/mage_ai/data_preparation/models/block/__init__.py\", line 2169, in execute_block_function\n    output = block_function_updated(*input_vars, **global_vars)\n  File \"<string>\", line 24, in load_data_from_postgres\n  File \"/usr/local/lib/python3.10/site-packages/mage_ai/io/sql.py\", line 216, in load\n    self.conn,\n  File \"/usr/local/lib/python3.10/site-packages/mage_ai/io/base.py\", line 405, in conn\n    raise ConnectionError(\nConnectionError: No connection currently open. Open a new connection to access this property.\n", "error_stack": ["  File \"/usr/local/bin/mage\", line 8, in <module>\n    sys.exit(app())\n", "  File \"/usr/local/lib/python3.10/site-packages/typer/main.py\", line 311, in __call__\n    return get_command(self)(*args, **kwargs)\n", "  File \"/usr/local/lib/python3.10/site-packages/click/core.py\", line 1161, in __call__\n    return self.main(*args, **kwargs)\n", "  File \"/usr/local/lib/python3.10/site-packages/typer/core.py\", line 778, in main\n    return _main(\n", "  File \"/usr/local/lib/python3.10/site-packages/typer/core.py\", line 216, in _main\n    rv = self.invoke(ctx)\n", "  File \"/usr/local/lib/python3.10/site-packages/click/core.py\", line 1697, in invoke\n    return _process_result(sub_ctx.command.invoke(sub_ctx))\n", "  File \"/usr/local/lib/python3.10/site-packages/click/core.py\", line 1443, in invoke\n    return ctx.invoke(self.callback, **ctx.params)\n", "  File \"/usr/local/lib/python3.10/site-packages/click/core.py\", line 788, in invoke\n    return __callback(*args, **kwargs)\n", "  File \"/usr/local/lib/python3.10/site-packages/typer/main.py\", line 683, in wrapper\n    return callback(**use_params)  # type: ignore\n", "  File \"/usr/local/lib/python3.10/site-packages/mage_ai/cli/main.py\", line 147, in start\n    start_server(\n", "  File \"/usr/local/lib/python3.10/site-packages/mage_ai/server/server.py\", line 809, in start_server\n    scheduler_manager.start_scheduler()\n", "  File \"/usr/local/lib/python3.10/site-packages/mage_ai/server/scheduler_manager.py\", line 106, in start_scheduler\n    proc.start()\n", "  File \"/usr/local/lib/python3.10/multiprocessing/process.py\", line 121, in start\n    self._popen = self._Popen(self)\n", "  File \"/usr/local/lib/python3.10/multiprocessing/context.py\", line 224, in _Popen\n    return _default_context.get_context().Process._Popen(process_obj)\n", "  File \"/usr/local/lib/python3.10/multiprocessing/context.py\", line 281, in _Popen\n    return Popen(process_obj)\n", "  File \"/usr/local/lib/python3.10/multiprocessing/popen_fork.py\", line 19, in __init__\n    self._launch(process_obj)\n", "  File \"/usr/local/lib/python3.10/multiprocessing/popen_fork.py\", line 71, in _launch\n    code = process_obj._bootstrap(parent_sentinel=child_r)\n", "  File \"/usr/local/lib/python3.10/multiprocessing/process.py\", line 314, in _bootstrap\n    self.run()\n", "  File \"/usr/local/lib/python3.10/multiprocessing/process.py\", line 108, in run\n    self._target(*self._args, **self._kwargs)\n", "  File \"/usr/local/lib/python3.10/site-packages/mage_ai/orchestration/db/process.py\", line 15, in start_session_and_run\n    results = target(*args)\n", "  File \"/usr/local/lib/python3.10/site-packages/mage_ai/server/scheduler_manager.py\", line 58, in run_scheduler\n    LoopTimeTrigger().start()\n", "  File \"/usr/local/lib/python3.10/site-packages/mage_ai/orchestration/triggers/loop_time_trigger.py\", line 14, in start\n    self.run()\n", "  File \"/usr/local/lib/python3.10/site-packages/mage_ai/orchestration/triggers/time_trigger.py\", line 11, in run\n    schedule_all()\n", "  File \"/usr/local/lib/python3.10/site-packages/mage_ai/orchestration/pipeline_scheduler_original.py\", line 1702, in schedule_all\n    PipelineScheduler(r).start()\n", "  File \"/usr/local/lib/python3.10/site-packages/mage_ai/orchestration/db/__init__.py\", line 159, in func_with_rollback\n    return func(*args, **kwargs)\n", "  File \"/usr/local/lib/python3.10/site-packages/mage_ai/orchestration/pipeline_scheduler_original.py\", line 197, in start\n    self.schedule()\n", "  File \"/usr/local/lib/python3.10/site-packages/mage_ai/orchestration/db/__init__.py\", line 159, in func_with_rollback\n    return func(*args, **kwargs)\n", "  File \"/usr/local/lib/python3.10/site-packages/mage_ai/orchestration/pipeline_scheduler_original.py\", line 333, in schedule\n    self.__schedule_blocks(block_runs)\n", "  File \"/usr/local/lib/python3.10/site-packages/mage_ai/orchestration/pipeline_scheduler_original.py\", line 640, in __schedule_blocks\n    job_manager.add_job(\n", "  File \"/usr/local/lib/python3.10/site-packages/mage_ai/orchestration/job_manager.py\", line 20, in add_job\n    self.queue.enqueue(job_id, target, *args, **kwargs)\n", "  File \"/usr/local/lib/python3.10/site-packages/mage_ai/orchestration/queue/process_queue.py\", line 121, in enqueue\n    self.start_worker_pool()\n", "  File \"/usr/local/lib/python3.10/site-packages/mage_ai/orchestration/queue/process_queue.py\", line 198, in start_worker_pool\n    self.worker_pool_proc.start()\n", "  File \"/usr/local/lib/python3.10/multiprocessing/process.py\", line 121, in start\n    self._popen = self._Popen(self)\n", "  File \"/usr/local/lib/python3.10/multiprocessing/context.py\", line 224, in _Popen\n    return _default_context.get_context().Process._Popen(process_obj)\n", "  File \"/usr/local/lib/python3.10/multiprocessing/context.py\", line 281, in _Popen\n    return Popen(process_obj)\n", "  File \"/usr/local/lib/python3.10/multiprocessing/popen_fork.py\", line 19, in __init__\n    self._launch(process_obj)\n", "  File \"/usr/local/lib/python3.10/multiprocessing/popen_fork.py\", line 71, in _launch\n    code = process_obj._bootstrap(parent_sentinel=child_r)\n", "  File \"/usr/local/lib/python3.10/multiprocessing/process.py\", line 314, in _bootstrap\n    self.run()\n", "  File \"/usr/local/lib/python3.10/multiprocessing/process.py\", line 108, in run\n    self._target(*self._args, **self._kwargs)\n", "  File \"/usr/local/lib/python3.10/site-packages/mage_ai/orchestration/queue/process_queue.py\", line 351, in poll_job_and_execute\n    worker.start()\n", "  File \"/usr/local/lib/python3.10/multiprocessing/process.py\", line 121, in start\n    self._popen = self._Popen(self)\n", "  File \"/usr/local/lib/python3.10/multiprocessing/context.py\", line 224, in _Popen\n    return _default_context.get_context().Process._Popen(process_obj)\n", "  File \"/usr/local/lib/python3.10/multiprocessing/context.py\", line 281, in _Popen\n    return Popen(process_obj)\n", "  File \"/usr/local/lib/python3.10/multiprocessing/popen_fork.py\", line 19, in __init__\n    self._launch(process_obj)\n", "  File \"/usr/local/lib/python3.10/multiprocessing/popen_fork.py\", line 71, in _launch\n    code = process_obj._bootstrap(parent_sentinel=child_r)\n", "  File \"/usr/local/lib/python3.10/multiprocessing/process.py\", line 314, in _bootstrap\n    self.run()\n", "  File \"/usr/local/lib/python3.10/site-packages/newrelic/api/background_task.py\", line 117, in wrapper\n    return wrapped(*args, **kwargs)\n", "  File \"/usr/local/lib/python3.10/site-packages/mage_ai/orchestration/queue/process_queue.py\", line 315, in run\n    start_session_and_run(args[1], *args[2], **args[3])\n", "  File \"/usr/local/lib/python3.10/site-packages/mage_ai/orchestration/db/process.py\", line 15, in start_session_and_run\n    results = target(*args)\n", "  File \"/usr/local/lib/python3.10/site-packages/mage_ai/orchestration/pipeline_scheduler_original.py\", line 1235, in run_block\n    return ExecutorFactory.get_block_executor(\n", "  File \"/usr/local/lib/python3.10/site-packages/mage_ai/data_preparation/executors/block_executor.py\", line 649, in execute\n    self.logger.exception(\n", "  File \"/usr/local/lib/python3.10/site-packages/mage_ai/data_preparation/logging/logger.py\", line 30, in exception\n    self.__send_message('exception', message, **kwargs)\n", "  File \"/usr/local/lib/python3.10/site-packages/mage_ai/data_preparation/logging/logger.py\", line 65, in __send_message\n    data['error_stack'] = traceback.format_stack()\n"], "error_stacktrace": "No connection currently open. Open a new connection to access this property."}
Traceback (most recent call last):
  File "/usr/local/lib/python3.10/site-packages/mage_ai/io/base.py", line 403, in conn
    return self._ctx
AttributeError: 'Postgres' object has no attribute '_ctx'

During handling of the above exception, another exception occurred:

Traceback (most recent call last):
  File "/usr/local/lib/python3.10/site-packages/mage_ai/data_preparation/executors/block_executor.py", line 647, in execute
    result = __execute_with_retry()
  File "/usr/local/lib/python3.10/site-packages/mage_ai/shared/retry.py", line 54, in retry_func
    raise e
  File "/usr/local/lib/python3.10/site-packages/mage_ai/shared/retry.py", line 38, in retry_func
    return func(*args, **kwargs)
  File "/usr/local/lib/python3.10/site-packages/mage_ai/data_preparation/executors/block_executor.py", line 621, in __execute_with_retry
    return self._execute(
  File "/usr/local/lib/python3.10/site-packages/mage_ai/data_preparation/executors/block_executor.py", line 1154, in _execute
    result = self.block.execute_sync(
  File "/usr/local/lib/python3.10/site-packages/mage_ai/data_preparation/models/block/__init__.py", line 1691, in execute_sync
    return __execute()
  File "/usr/local/lib/python3.10/site-packages/mage_ai/data_preparation/models/block/__init__.py", line 1668, in __execute
    raise err
  File "/usr/local/lib/python3.10/site-packages/mage_ai/data_preparation/models/block/__init__.py", line 1570, in __execute
    output = self.execute_block(
  File "/usr/local/lib/python3.10/site-packages/mage_ai/data_preparation/models/block/__init__.py", line 1910, in execute_block
    outputs = self._execute_block(
  File "/usr/local/lib/python3.10/site-packages/mage_ai/data_preparation/models/block/__init__.py", line 2073, in _execute_block
    outputs = self.execute_block_function(
  File "/usr/local/lib/python3.10/site-packages/mage_ai/data_preparation/models/block/__init__.py", line 2169, in execute_block_function
    output = block_function_updated(*input_vars, **global_vars)
  File "<string>", line 24, in load_data_from_postgres
  File "/usr/local/lib/python3.10/site-packages/mage_ai/io/sql.py", line 216, in load
    self.conn,
  File "/usr/local/lib/python3.10/site-packages/mage_ai/io/base.py", line 405, in conn
    raise ConnectionError(
ConnectionError: No connection currently open. Open a new connection to access this property.
