2025-02-16T22:04:06 {"block_run_id": 49, "block_uuid": "lecturadatos", "pipeline_run_id": 17, "pipeline_schedule_id": 1, "pipeline_uuid": "descuento", "hostname": "c267f280891a", "block_type": "data_loader", "level": "INFO", "message": "Start executing block with BlockExecutor.", "timestamp": 1739743446.861207, "uuid": "47193e216dff417d803ec11e8632c034"}
2025-02-16T22:04:06 {"block_run_id": 49, "block_uuid": "lecturadatos", "pipeline_run_id": 17, "pipeline_schedule_id": 1, "pipeline_uuid": "descuento", "hostname": "c267f280891a", "block_type": "data_loader", "level": "INFO", "message": "Postgres initialized", "timestamp": 1739743446.99564, "uuid": "3b6a525a01cc4e8a9b9537ad30fc7bfc"}
2025-02-16T22:04:06 {"block_run_id": 49, "block_uuid": "lecturadatos", "pipeline_run_id": 17, "pipeline_schedule_id": 1, "pipeline_uuid": "descuento", "hostname": "c267f280891a", "block_type": "data_loader", "level": "INFO", "message": "\u2514\u2500 Opening connection to PostgreSQL database...", "timestamp": 1739743446.996244, "uuid": "8e72df7440494f6d82ed8f8e63eb8689"}
2025-02-16T22:04:07 {"block_run_id": 49, "block_uuid": "lecturadatos", "pipeline_run_id": 17, "pipeline_schedule_id": 1, "pipeline_uuid": "descuento", "hostname": "c267f280891a", "block_type": "data_loader", "level": "INFO", "message": "Traceback (most recent call last):", "timestamp": 1739743447.01592, "uuid": "5b4d2f11a5d14412bf3b84b33e436316"}
2025-02-16T22:04:07 {"block_run_id": 49, "block_uuid": "lecturadatos", "pipeline_run_id": 17, "pipeline_schedule_id": 1, "pipeline_uuid": "descuento", "hostname": "c267f280891a", "block_type": "data_loader", "level": "INFO", "message": "  File \"/usr/local/lib/python3.10/site-packages/mage_ai/io/postgres.py\", line 163, in open", "timestamp": 1739743447.016286, "uuid": "1ee910ab304449f183cd62cf0c5b2009"}
2025-02-16T22:04:07 {"block_run_id": 49, "block_uuid": "lecturadatos", "pipeline_run_id": 17, "pipeline_schedule_id": 1, "pipeline_uuid": "descuento", "hostname": "c267f280891a", "block_type": "data_loader", "level": "INFO", "message": "    self._ctx = connect(**connect_opts)", "timestamp": 1739743447.016533, "uuid": "d83bc1e645b5492d8d5db21664fccaa8"}
2025-02-16T22:04:07 {"block_run_id": 49, "block_uuid": "lecturadatos", "pipeline_run_id": 17, "pipeline_schedule_id": 1, "pipeline_uuid": "descuento", "hostname": "c267f280891a", "block_type": "data_loader", "level": "INFO", "message": "  File \"/usr/local/lib/python3.10/site-packages/psycopg2/__init__.py\", line 122, in connect", "timestamp": 1739743447.016794, "uuid": "98c0225946df4f34a139a009ff433f20"}
2025-02-16T22:04:07 {"block_run_id": 49, "block_uuid": "lecturadatos", "pipeline_run_id": 17, "pipeline_schedule_id": 1, "pipeline_uuid": "descuento", "hostname": "c267f280891a", "block_type": "data_loader", "level": "INFO", "message": "    conn = _connect(dsn, connection_factory=connection_factory, **kwasync)", "timestamp": 1739743447.017038, "uuid": "444d22d6f3c5499495c8c8f109a403a3"}
2025-02-16T22:04:07 {"block_run_id": 49, "block_uuid": "lecturadatos", "pipeline_run_id": 17, "pipeline_schedule_id": 1, "pipeline_uuid": "descuento", "hostname": "c267f280891a", "block_type": "data_loader", "level": "INFO", "message": "psycopg2.OperationalError: connection to server at \"postgres\" (172.21.0.2), port 5432 failed: FATAL:  could not open file \"base/16384/2601\": Permission denied", "timestamp": 1739743447.017282, "uuid": "f7110bf4d98141cb82083e947f93f530"}
2025-02-16T22:04:07 {"block_run_id": 49, "block_uuid": "lecturadatos", "pipeline_run_id": 17, "pipeline_schedule_id": 1, "pipeline_uuid": "descuento", "hostname": "c267f280891a", "block_type": "data_loader", "level": "INFO", "message": "DONE", "timestamp": 1739743447.017573, "uuid": "837ada74cb434d47b5fed189c8b42fbf"}
2025-02-16T22:04:07 {"block_run_id": 49, "block_uuid": "lecturadatos", "pipeline_run_id": 17, "pipeline_schedule_id": 1, "pipeline_uuid": "descuento", "hostname": "c267f280891a", "block_type": "data_loader", "level": "INFO", "message": "", "timestamp": 1739743447.017876, "uuid": "da1f1d6e8aba4f2783d087d61bfeb8cd"}
2025-02-16T22:04:07 {"block_run_id": 49, "block_uuid": "lecturadatos", "pipeline_run_id": 17, "pipeline_schedule_id": 1, "pipeline_uuid": "descuento", "hostname": "c267f280891a", "block_type": "data_loader", "level": "INFO", "message": "\u251c\u2500", "timestamp": 1739743447.018092, "uuid": "885b02b6fba346efb26c91041c0bd3b3"}
2025-02-16T22:04:07 {"block_run_id": 49, "block_uuid": "lecturadatos", "pipeline_run_id": 17, "pipeline_schedule_id": 1, "pipeline_uuid": "descuento", "hostname": "c267f280891a", "block_type": "data_loader", "level": "INFO", "message": "\u2514\u2500 Loading data with query", "timestamp": 1739743447.018309, "uuid": "7cc7116c7071495084ffc01569c9d500"}
2025-02-16T22:04:07 {"block_run_id": 49, "block_uuid": "lecturadatos", "pipeline_run_id": 17, "pipeline_schedule_id": 1, "pipeline_uuid": "descuento", "hostname": "c267f280891a", "block_type": "data_loader", "level": "INFO", "message": "", "timestamp": 1739743447.018508, "uuid": "0c575d51f41e4798a728d456e32f7d45"}
2025-02-16T22:04:07 {"block_run_id": 49, "block_uuid": "lecturadatos", "pipeline_run_id": 17, "pipeline_schedule_id": 1, "pipeline_uuid": "descuento", "hostname": "c267f280891a", "block_type": "data_loader", "level": "INFO", "message": "SELECT * FROM productos", "timestamp": 1739743447.018706, "uuid": "530b0c4b72a648428270af3ecd4913ab"}
2025-02-16T22:04:07 {"block_run_id": 49, "block_uuid": "lecturadatos", "pipeline_run_id": 17, "pipeline_schedule_id": 1, "pipeline_uuid": "descuento", "hostname": "c267f280891a", "block_type": "data_loader", "level": "INFO", "message": "", "timestamp": 1739743447.018913, "uuid": "9a34c3370e654b0d9e83e4b7a7c37d73"}
2025-02-16T22:04:07 {"block_run_id": 49, "block_uuid": "lecturadatos", "pipeline_run_id": 17, "pipeline_schedule_id": 1, "pipeline_uuid": "descuento", "hostname": "c267f280891a", "block_type": "data_loader", "level": "INFO", "message": "...", "timestamp": 1739743447.019134, "uuid": "7e8ad3e38e3a40728a40905c2a2830c9"}
2025-02-16T22:04:07 {"block_run_id": 49, "block_uuid": "lecturadatos", "pipeline_run_id": 17, "pipeline_schedule_id": 1, "pipeline_uuid": "descuento", "hostname": "c267f280891a", "block_type": "data_loader", "level": "WARNING", "message": "Exception thrown when attempting to run <function BlockExecutor.execute.<locals>.__execute_with_retry at 0x7f64592b67a0>, attempt 1 of 1", "timestamp": 1739743447.019745, "uuid": "a7decf74da734b3794eba2c0548a4bb8", "error": "Traceback (most recent call last):\n  File \"/usr/local/lib/python3.10/site-packages/mage_ai/io/base.py\", line 403, in conn\n    return self._ctx\nAttributeError: 'Postgres' object has no attribute '_ctx'\n\nDuring handling of the above exception, another exception occurred:\n\nTraceback (most recent call last):\n  File \"/usr/local/lib/python3.10/site-packages/mage_ai/shared/retry.py\", line 38, in retry_func\n    return func(*args, **kwargs)\n  File \"/usr/local/lib/python3.10/site-packages/mage_ai/data_preparation/executors/block_executor.py\", line 621, in __execute_with_retry\n    return self._execute(\n  File \"/usr/local/lib/python3.10/site-packages/mage_ai/data_preparation/executors/block_executor.py\", line 1154, in _execute\n    result = self.block.execute_sync(\n  File \"/usr/local/lib/python3.10/site-packages/mage_ai/data_preparation/models/block/__init__.py\", line 1691, in execute_sync\n    return __execute()\n  File \"/usr/local/lib/python3.10/site-packages/mage_ai/data_preparation/models/block/__init__.py\", line 1668, in __execute\n    raise err\n  File \"/usr/local/lib/python3.10/site-packages/mage_ai/data_preparation/models/block/__init__.py\", line 1570, in __execute\n    output = self.execute_block(\n  File \"/usr/local/lib/python3.10/site-packages/mage_ai/data_preparation/models/block/__init__.py\", line 1910, in execute_block\n    outputs = self._execute_block(\n  File \"/usr/local/lib/python3.10/site-packages/mage_ai/data_preparation/models/block/__init__.py\", line 2073, in _execute_block\n    outputs = self.execute_block_function(\n  File \"/usr/local/lib/python3.10/site-packages/mage_ai/data_preparation/models/block/__init__.py\", line 2169, in execute_block_function\n    output = block_function_updated(*input_vars, **global_vars)\n  File \"<string>\", line 24, in load_data_from_postgres\n  File \"/usr/local/lib/python3.10/site-packages/mage_ai/io/sql.py\", line 216, in load\n    self.conn,\n  File \"/usr/local/lib/python3.10/site-packages/mage_ai/io/base.py\", line 405, in conn\n    raise ConnectionError(\nConnectionError: No connection currently open. Open a new connection to access this property.\n", "error_stack": ["  File \"/usr/local/bin/mage\", line 8, in <module>\n    sys.exit(app())\n", "  File \"/usr/local/lib/python3.10/site-packages/typer/main.py\", line 311, in __call__\n    return get_command(self)(*args, **kwargs)\n", "  File \"/usr/local/lib/python3.10/site-packages/click/core.py\", line 1161, in __call__\n    return self.main(*args, **kwargs)\n", "  File \"/usr/local/lib/python3.10/site-packages/typer/core.py\", line 778, in main\n    return _main(\n", "  File \"/usr/local/lib/python3.10/site-packages/typer/core.py\", line 216, in _main\n    rv = self.invoke(ctx)\n", "  File \"/usr/local/lib/python3.10/site-packages/click/core.py\", line 1697, in invoke\n    return _process_result(sub_ctx.command.invoke(sub_ctx))\n", "  File \"/usr/local/lib/python3.10/site-packages/click/core.py\", line 1443, in invoke\n    return ctx.invoke(self.callback, **ctx.params)\n", "  File \"/usr/local/lib/python3.10/site-packages/click/core.py\", line 788, in invoke\n    return __callback(*args, **kwargs)\n", "  File \"/usr/local/lib/python3.10/site-packages/typer/main.py\", line 683, in wrapper\n    return callback(**use_params)  # type: ignore\n", "  File \"/usr/local/lib/python3.10/site-packages/mage_ai/cli/main.py\", line 147, in start\n    start_server(\n", "  File \"/usr/local/lib/python3.10/site-packages/mage_ai/server/server.py\", line 809, in start_server\n    scheduler_manager.start_scheduler()\n", "  File \"/usr/local/lib/python3.10/site-packages/mage_ai/server/scheduler_manager.py\", line 106, in start_scheduler\n    proc.start()\n", "  File \"/usr/local/lib/python3.10/multiprocessing/process.py\", line 121, in start\n    self._popen = self._Popen(self)\n", "  File \"/usr/local/lib/python3.10/multiprocessing/context.py\", line 224, in _Popen\n    return _default_context.get_context().Process._Popen(process_obj)\n", "  File \"/usr/local/lib/python3.10/multiprocessing/context.py\", line 281, in _Popen\n    return Popen(process_obj)\n", "  File \"/usr/local/lib/python3.10/multiprocessing/popen_fork.py\", line 19, in __init__\n    self._launch(process_obj)\n", "  File \"/usr/local/lib/python3.10/multiprocessing/popen_fork.py\", line 71, in _launch\n    code = process_obj._bootstrap(parent_sentinel=child_r)\n", "  File \"/usr/local/lib/python3.10/multiprocessing/process.py\", line 314, in _bootstrap\n    self.run()\n", "  File \"/usr/local/lib/python3.10/multiprocessing/process.py\", line 108, in run\n    self._target(*self._args, **self._kwargs)\n", "  File \"/usr/local/lib/python3.10/site-packages/mage_ai/orchestration/db/process.py\", line 15, in start_session_and_run\n    results = target(*args)\n", "  File \"/usr/local/lib/python3.10/site-packages/mage_ai/server/scheduler_manager.py\", line 58, in run_scheduler\n    LoopTimeTrigger().start()\n", "  File \"/usr/local/lib/python3.10/site-packages/mage_ai/orchestration/triggers/loop_time_trigger.py\", line 14, in start\n    self.run()\n", "  File \"/usr/local/lib/python3.10/site-packages/mage_ai/orchestration/triggers/time_trigger.py\", line 11, in run\n    schedule_all()\n", "  File \"/usr/local/lib/python3.10/site-packages/mage_ai/orchestration/pipeline_scheduler_original.py\", line 1702, in schedule_all\n    PipelineScheduler(r).start()\n", "  File \"/usr/local/lib/python3.10/site-packages/mage_ai/orchestration/db/__init__.py\", line 159, in func_with_rollback\n    return func(*args, **kwargs)\n", "  File \"/usr/local/lib/python3.10/site-packages/mage_ai/orchestration/pipeline_scheduler_original.py\", line 197, in start\n    self.schedule()\n", "  File \"/usr/local/lib/python3.10/site-packages/mage_ai/orchestration/db/__init__.py\", line 159, in func_with_rollback\n    return func(*args, **kwargs)\n", "  File \"/usr/local/lib/python3.10/site-packages/mage_ai/orchestration/pipeline_scheduler_original.py\", line 333, in schedule\n    self.__schedule_blocks(block_runs)\n", "  File \"/usr/local/lib/python3.10/site-packages/mage_ai/orchestration/pipeline_scheduler_original.py\", line 640, in __schedule_blocks\n    job_manager.add_job(\n", "  File \"/usr/local/lib/python3.10/site-packages/mage_ai/orchestration/job_manager.py\", line 20, in add_job\n    self.queue.enqueue(job_id, target, *args, **kwargs)\n", "  File \"/usr/local/lib/python3.10/site-packages/mage_ai/orchestration/queue/process_queue.py\", line 121, in enqueue\n    self.start_worker_pool()\n", "  File \"/usr/local/lib/python3.10/site-packages/mage_ai/orchestration/queue/process_queue.py\", line 198, in start_worker_pool\n    self.worker_pool_proc.start()\n", "  File \"/usr/local/lib/python3.10/multiprocessing/process.py\", line 121, in start\n    self._popen = self._Popen(self)\n", "  File \"/usr/local/lib/python3.10/multiprocessing/context.py\", line 224, in _Popen\n    return _default_context.get_context().Process._Popen(process_obj)\n", "  File \"/usr/local/lib/python3.10/multiprocessing/context.py\", line 281, in _Popen\n    return Popen(process_obj)\n", "  File \"/usr/local/lib/python3.10/multiprocessing/popen_fork.py\", line 19, in __init__\n    self._launch(process_obj)\n", "  File \"/usr/local/lib/python3.10/multiprocessing/popen_fork.py\", line 71, in _launch\n    code = process_obj._bootstrap(parent_sentinel=child_r)\n", "  File \"/usr/local/lib/python3.10/multiprocessing/process.py\", line 314, in _bootstrap\n    self.run()\n", "  File \"/usr/local/lib/python3.10/multiprocessing/process.py\", line 108, in run\n    self._target(*self._args, **self._kwargs)\n", "  File \"/usr/local/lib/python3.10/site-packages/mage_ai/orchestration/queue/process_queue.py\", line 351, in poll_job_and_execute\n    worker.start()\n", "  File \"/usr/local/lib/python3.10/multiprocessing/process.py\", line 121, in start\n    self._popen = self._Popen(self)\n", "  File \"/usr/local/lib/python3.10/multiprocessing/context.py\", line 224, in _Popen\n    return _default_context.get_context().Process._Popen(process_obj)\n", "  File \"/usr/local/lib/python3.10/multiprocessing/context.py\", line 281, in _Popen\n    return Popen(process_obj)\n", "  File \"/usr/local/lib/python3.10/multiprocessing/popen_fork.py\", line 19, in __init__\n    self._launch(process_obj)\n", "  File \"/usr/local/lib/python3.10/multiprocessing/popen_fork.py\", line 71, in _launch\n    code = process_obj._bootstrap(parent_sentinel=child_r)\n", "  File \"/usr/local/lib/python3.10/multiprocessing/process.py\", line 314, in _bootstrap\n    self.run()\n", "  File \"/usr/local/lib/python3.10/site-packages/newrelic/api/background_task.py\", line 117, in wrapper\n    return wrapped(*args, **kwargs)\n", "  File \"/usr/local/lib/python3.10/site-packages/mage_ai/orchestration/queue/process_queue.py\", line 315, in run\n    start_session_and_run(args[1], *args[2], **args[3])\n", "  File \"/usr/local/lib/python3.10/site-packages/mage_ai/orchestration/db/process.py\", line 15, in start_session_and_run\n    results = target(*args)\n", "  File \"/usr/local/lib/python3.10/site-packages/mage_ai/orchestration/pipeline_scheduler_original.py\", line 1235, in run_block\n    return ExecutorFactory.get_block_executor(\n", "  File \"/usr/local/lib/python3.10/site-packages/mage_ai/data_preparation/executors/block_executor.py\", line 647, in execute\n    result = __execute_with_retry()\n", "  File \"/usr/local/lib/python3.10/site-packages/mage_ai/shared/retry.py\", line 46, in retry_func\n    logger.warning(\n", "  File \"/usr/local/lib/python3.10/site-packages/mage_ai/data_preparation/logging/logger.py\", line 39, in warning\n    self.__send_message('warning', message, **kwargs)\n", "  File \"/usr/local/lib/python3.10/site-packages/mage_ai/data_preparation/logging/logger.py\", line 65, in __send_message\n    data['error_stack'] = traceback.format_stack()\n"], "error_stacktrace": "No connection currently open. Open a new connection to access this property."}
2025-02-16T22:04:07 {"block_run_id": 49, "block_uuid": "lecturadatos", "pipeline_run_id": 17, "pipeline_schedule_id": 1, "pipeline_uuid": "descuento", "hostname": "c267f280891a", "block_type": "data_loader", "level": "EXCEPTION", "message": "Failed to execute block lecturadatos", "timestamp": 1739743447.025757, "uuid": "e930136007c94f319b972b2b6d9c1e98", "error": "Traceback (most recent call last):\n  File \"/usr/local/lib/python3.10/site-packages/mage_ai/io/base.py\", line 403, in conn\n    return self._ctx\nAttributeError: 'Postgres' object has no attribute '_ctx'\n\nDuring handling of the above exception, another exception occurred:\n\nTraceback (most recent call last):\n  File \"/usr/local/lib/python3.10/site-packages/mage_ai/data_preparation/executors/block_executor.py\", line 647, in execute\n    result = __execute_with_retry()\n  File \"/usr/local/lib/python3.10/site-packages/mage_ai/shared/retry.py\", line 54, in retry_func\n    raise e\n  File \"/usr/local/lib/python3.10/site-packages/mage_ai/shared/retry.py\", line 38, in retry_func\n    return func(*args, **kwargs)\n  File \"/usr/local/lib/python3.10/site-packages/mage_ai/data_preparation/executors/block_executor.py\", line 621, in __execute_with_retry\n    return self._execute(\n  File \"/usr/local/lib/python3.10/site-packages/mage_ai/data_preparation/executors/block_executor.py\", line 1154, in _execute\n    result = self.block.execute_sync(\n  File \"/usr/local/lib/python3.10/site-packages/mage_ai/data_preparation/models/block/__init__.py\", line 1691, in execute_sync\n    return __execute()\n  File \"/usr/local/lib/python3.10/site-packages/mage_ai/data_preparation/models/block/__init__.py\", line 1668, in __execute\n    raise err\n  File \"/usr/local/lib/python3.10/site-packages/mage_ai/data_preparation/models/block/__init__.py\", line 1570, in __execute\n    output = self.execute_block(\n  File \"/usr/local/lib/python3.10/site-packages/mage_ai/data_preparation/models/block/__init__.py\", line 1910, in execute_block\n    outputs = self._execute_block(\n  File \"/usr/local/lib/python3.10/site-packages/mage_ai/data_preparation/models/block/__init__.py\", line 2073, in _execute_block\n    outputs = self.execute_block_function(\n  File \"/usr/local/lib/python3.10/site-packages/mage_ai/data_preparation/models/block/__init__.py\", line 2169, in execute_block_function\n    output = block_function_updated(*input_vars, **global_vars)\n  File \"<string>\", line 24, in load_data_from_postgres\n  File \"/usr/local/lib/python3.10/site-packages/mage_ai/io/sql.py\", line 216, in load\n    self.conn,\n  File \"/usr/local/lib/python3.10/site-packages/mage_ai/io/base.py\", line 405, in conn\n    raise ConnectionError(\nConnectionError: No connection currently open. Open a new connection to access this property.\n", "error_stack": ["  File \"/usr/local/bin/mage\", line 8, in <module>\n    sys.exit(app())\n", "  File \"/usr/local/lib/python3.10/site-packages/typer/main.py\", line 311, in __call__\n    return get_command(self)(*args, **kwargs)\n", "  File \"/usr/local/lib/python3.10/site-packages/click/core.py\", line 1161, in __call__\n    return self.main(*args, **kwargs)\n", "  File \"/usr/local/lib/python3.10/site-packages/typer/core.py\", line 778, in main\n    return _main(\n", "  File \"/usr/local/lib/python3.10/site-packages/typer/core.py\", line 216, in _main\n    rv = self.invoke(ctx)\n", "  File \"/usr/local/lib/python3.10/site-packages/click/core.py\", line 1697, in invoke\n    return _process_result(sub_ctx.command.invoke(sub_ctx))\n", "  File \"/usr/local/lib/python3.10/site-packages/click/core.py\", line 1443, in invoke\n    return ctx.invoke(self.callback, **ctx.params)\n", "  File \"/usr/local/lib/python3.10/site-packages/click/core.py\", line 788, in invoke\n    return __callback(*args, **kwargs)\n", "  File \"/usr/local/lib/python3.10/site-packages/typer/main.py\", line 683, in wrapper\n    return callback(**use_params)  # type: ignore\n", "  File \"/usr/local/lib/python3.10/site-packages/mage_ai/cli/main.py\", line 147, in start\n    start_server(\n", "  File \"/usr/local/lib/python3.10/site-packages/mage_ai/server/server.py\", line 809, in start_server\n    scheduler_manager.start_scheduler()\n", "  File \"/usr/local/lib/python3.10/site-packages/mage_ai/server/scheduler_manager.py\", line 106, in start_scheduler\n    proc.start()\n", "  File \"/usr/local/lib/python3.10/multiprocessing/process.py\", line 121, in start\n    self._popen = self._Popen(self)\n", "  File \"/usr/local/lib/python3.10/multiprocessing/context.py\", line 224, in _Popen\n    return _default_context.get_context().Process._Popen(process_obj)\n", "  File \"/usr/local/lib/python3.10/multiprocessing/context.py\", line 281, in _Popen\n    return Popen(process_obj)\n", "  File \"/usr/local/lib/python3.10/multiprocessing/popen_fork.py\", line 19, in __init__\n    self._launch(process_obj)\n", "  File \"/usr/local/lib/python3.10/multiprocessing/popen_fork.py\", line 71, in _launch\n    code = process_obj._bootstrap(parent_sentinel=child_r)\n", "  File \"/usr/local/lib/python3.10/multiprocessing/process.py\", line 314, in _bootstrap\n    self.run()\n", "  File \"/usr/local/lib/python3.10/multiprocessing/process.py\", line 108, in run\n    self._target(*self._args, **self._kwargs)\n", "  File \"/usr/local/lib/python3.10/site-packages/mage_ai/orchestration/db/process.py\", line 15, in start_session_and_run\n    results = target(*args)\n", "  File \"/usr/local/lib/python3.10/site-packages/mage_ai/server/scheduler_manager.py\", line 58, in run_scheduler\n    LoopTimeTrigger().start()\n", "  File \"/usr/local/lib/python3.10/site-packages/mage_ai/orchestration/triggers/loop_time_trigger.py\", line 14, in start\n    self.run()\n", "  File \"/usr/local/lib/python3.10/site-packages/mage_ai/orchestration/triggers/time_trigger.py\", line 11, in run\n    schedule_all()\n", "  File \"/usr/local/lib/python3.10/site-packages/mage_ai/orchestration/pipeline_scheduler_original.py\", line 1702, in schedule_all\n    PipelineScheduler(r).start()\n", "  File \"/usr/local/lib/python3.10/site-packages/mage_ai/orchestration/db/__init__.py\", line 159, in func_with_rollback\n    return func(*args, **kwargs)\n", "  File \"/usr/local/lib/python3.10/site-packages/mage_ai/orchestration/pipeline_scheduler_original.py\", line 197, in start\n    self.schedule()\n", "  File \"/usr/local/lib/python3.10/site-packages/mage_ai/orchestration/db/__init__.py\", line 159, in func_with_rollback\n    return func(*args, **kwargs)\n", "  File \"/usr/local/lib/python3.10/site-packages/mage_ai/orchestration/pipeline_scheduler_original.py\", line 333, in schedule\n    self.__schedule_blocks(block_runs)\n", "  File \"/usr/local/lib/python3.10/site-packages/mage_ai/orchestration/pipeline_scheduler_original.py\", line 640, in __schedule_blocks\n    job_manager.add_job(\n", "  File \"/usr/local/lib/python3.10/site-packages/mage_ai/orchestration/job_manager.py\", line 20, in add_job\n    self.queue.enqueue(job_id, target, *args, **kwargs)\n", "  File \"/usr/local/lib/python3.10/site-packages/mage_ai/orchestration/queue/process_queue.py\", line 121, in enqueue\n    self.start_worker_pool()\n", "  File \"/usr/local/lib/python3.10/site-packages/mage_ai/orchestration/queue/process_queue.py\", line 198, in start_worker_pool\n    self.worker_pool_proc.start()\n", "  File \"/usr/local/lib/python3.10/multiprocessing/process.py\", line 121, in start\n    self._popen = self._Popen(self)\n", "  File \"/usr/local/lib/python3.10/multiprocessing/context.py\", line 224, in _Popen\n    return _default_context.get_context().Process._Popen(process_obj)\n", "  File \"/usr/local/lib/python3.10/multiprocessing/context.py\", line 281, in _Popen\n    return Popen(process_obj)\n", "  File \"/usr/local/lib/python3.10/multiprocessing/popen_fork.py\", line 19, in __init__\n    self._launch(process_obj)\n", "  File \"/usr/local/lib/python3.10/multiprocessing/popen_fork.py\", line 71, in _launch\n    code = process_obj._bootstrap(parent_sentinel=child_r)\n", "  File \"/usr/local/lib/python3.10/multiprocessing/process.py\", line 314, in _bootstrap\n    self.run()\n", "  File \"/usr/local/lib/python3.10/multiprocessing/process.py\", line 108, in run\n    self._target(*self._args, **self._kwargs)\n", "  File \"/usr/local/lib/python3.10/site-packages/mage_ai/orchestration/queue/process_queue.py\", line 351, in poll_job_and_execute\n    worker.start()\n", "  File \"/usr/local/lib/python3.10/multiprocessing/process.py\", line 121, in start\n    self._popen = self._Popen(self)\n", "  File \"/usr/local/lib/python3.10/multiprocessing/context.py\", line 224, in _Popen\n    return _default_context.get_context().Process._Popen(process_obj)\n", "  File \"/usr/local/lib/python3.10/multiprocessing/context.py\", line 281, in _Popen\n    return Popen(process_obj)\n", "  File \"/usr/local/lib/python3.10/multiprocessing/popen_fork.py\", line 19, in __init__\n    self._launch(process_obj)\n", "  File \"/usr/local/lib/python3.10/multiprocessing/popen_fork.py\", line 71, in _launch\n    code = process_obj._bootstrap(parent_sentinel=child_r)\n", "  File \"/usr/local/lib/python3.10/multiprocessing/process.py\", line 314, in _bootstrap\n    self.run()\n", "  File \"/usr/local/lib/python3.10/site-packages/newrelic/api/background_task.py\", line 117, in wrapper\n    return wrapped(*args, **kwargs)\n", "  File \"/usr/local/lib/python3.10/site-packages/mage_ai/orchestration/queue/process_queue.py\", line 315, in run\n    start_session_and_run(args[1], *args[2], **args[3])\n", "  File \"/usr/local/lib/python3.10/site-packages/mage_ai/orchestration/db/process.py\", line 15, in start_session_and_run\n    results = target(*args)\n", "  File \"/usr/local/lib/python3.10/site-packages/mage_ai/orchestration/pipeline_scheduler_original.py\", line 1235, in run_block\n    return ExecutorFactory.get_block_executor(\n", "  File \"/usr/local/lib/python3.10/site-packages/mage_ai/data_preparation/executors/block_executor.py\", line 649, in execute\n    self.logger.exception(\n", "  File \"/usr/local/lib/python3.10/site-packages/mage_ai/data_preparation/logging/logger.py\", line 30, in exception\n    self.__send_message('exception', message, **kwargs)\n", "  File \"/usr/local/lib/python3.10/site-packages/mage_ai/data_preparation/logging/logger.py\", line 65, in __send_message\n    data['error_stack'] = traceback.format_stack()\n"], "error_stacktrace": "No connection currently open. Open a new connection to access this property."}
Traceback (most recent call last):
  File "/usr/local/lib/python3.10/site-packages/mage_ai/io/base.py", line 403, in conn
    return self._ctx
AttributeError: 'Postgres' object has no attribute '_ctx'

During handling of the above exception, another exception occurred:

Traceback (most recent call last):
  File "/usr/local/lib/python3.10/site-packages/mage_ai/data_preparation/executors/block_executor.py", line 647, in execute
    result = __execute_with_retry()
  File "/usr/local/lib/python3.10/site-packages/mage_ai/shared/retry.py", line 54, in retry_func
    raise e
  File "/usr/local/lib/python3.10/site-packages/mage_ai/shared/retry.py", line 38, in retry_func
    return func(*args, **kwargs)
  File "/usr/local/lib/python3.10/site-packages/mage_ai/data_preparation/executors/block_executor.py", line 621, in __execute_with_retry
    return self._execute(
  File "/usr/local/lib/python3.10/site-packages/mage_ai/data_preparation/executors/block_executor.py", line 1154, in _execute
    result = self.block.execute_sync(
  File "/usr/local/lib/python3.10/site-packages/mage_ai/data_preparation/models/block/__init__.py", line 1691, in execute_sync
    return __execute()
  File "/usr/local/lib/python3.10/site-packages/mage_ai/data_preparation/models/block/__init__.py", line 1668, in __execute
    raise err
  File "/usr/local/lib/python3.10/site-packages/mage_ai/data_preparation/models/block/__init__.py", line 1570, in __execute
    output = self.execute_block(
  File "/usr/local/lib/python3.10/site-packages/mage_ai/data_preparation/models/block/__init__.py", line 1910, in execute_block
    outputs = self._execute_block(
  File "/usr/local/lib/python3.10/site-packages/mage_ai/data_preparation/models/block/__init__.py", line 2073, in _execute_block
    outputs = self.execute_block_function(
  File "/usr/local/lib/python3.10/site-packages/mage_ai/data_preparation/models/block/__init__.py", line 2169, in execute_block_function
    output = block_function_updated(*input_vars, **global_vars)
  File "<string>", line 24, in load_data_from_postgres
  File "/usr/local/lib/python3.10/site-packages/mage_ai/io/sql.py", line 216, in load
    self.conn,
  File "/usr/local/lib/python3.10/site-packages/mage_ai/io/base.py", line 405, in conn
    raise ConnectionError(
ConnectionError: No connection currently open. Open a new connection to access this property.
