2025-02-16T22:09:00 {"cpu": 0.24365234375, "cpu_total": 8, "cpu_usage": 0.03045654296875, "memory": 1283.0, "memory_total": 4842.0, "memory_usage": 0.264973151590252, "pipeline_run_id": 23, "pipeline_schedule_id": 1, "pipeline_uuid": "descuento", "hostname": "e48b74cc7123", "level": "INFO", "message": "Pipeline descuento for run 23 in schedule 1 is alive.", "timestamp": 1739743740.480459, "uuid": "35931e0fe9784809b31672f2d1aefcdf"}
2025-02-16T22:09:00 {"cpu": 0.24365234375, "cpu_total": 8, "cpu_usage": 0.03045654296875, "memory": 1296.0, "memory_total": 4842.0, "memory_usage": 0.26765799256505574, "pipeline_run_id": 23, "pipeline_schedule_id": 1, "pipeline_uuid": "descuento", "hostname": "e48b74cc7123", "level": "INFO", "message": "Pipeline descuento for run 23 in schedule 1 is alive.", "timestamp": 1739743740.54646, "uuid": "fa2623e8a5aa48799523652160147775"}
2025-02-16T22:09:00 {"block_run_id": 67, "block_uuid": "lecturadatos", "pipeline_run_id": 23, "pipeline_schedule_id": 1, "pipeline_uuid": "descuento", "hostname": "e48b74cc7123", "level": "INFO", "message": "Execute PipelineRun 23, BlockRun 67: pipeline descuento block lecturadatos", "timestamp": 1739743740.596795, "uuid": "abb2ddda3d5c475c891d6bba7faed0b6"}
2025-02-16T22:09:00 {"block_run_id": 67, "block_uuid": "lecturadatos", "pipeline_run_id": 23, "pipeline_schedule_id": 1, "pipeline_uuid": "descuento", "hostname": "e48b74cc7123", "level": "INFO", "message": "BlockRun 67 (block_uuid: lecturadatos) completes.", "timestamp": 1739743740.756888, "uuid": "ba199fd908df4ae3b529292ba4ef68b5"}
2025-02-16T22:16:08 {"cpu": 0.015625, "cpu_total": 8, "cpu_usage": 0.001953125, "memory": 1154.0, "memory_total": 4842.0, "memory_usage": 0.23833126807104502, "pipeline_run_id": 23, "pipeline_schedule_id": 1, "pipeline_uuid": "descuento", "hostname": "d79e8dc5d15d", "level": "INFO", "message": "Pipeline descuento for run 23 in schedule 1 is alive.", "timestamp": 1739744168.694765, "uuid": "5c0ed55d07224eee88a76d11f5bca1dd"}
2025-02-16T22:16:09 {"block_run_id": 68, "block_uuid": "transformaciondatos", "pipeline_run_id": 23, "pipeline_schedule_id": 1, "pipeline_uuid": "descuento", "hostname": "d79e8dc5d15d", "level": "INFO", "message": "Execute PipelineRun 23, BlockRun 68: pipeline descuento block transformaciondatos", "timestamp": 1739744169.730989, "uuid": "0db353ce3c4d41c483ddb09901548eb9"}
2025-02-16T22:16:09 {"block_run_id": 68, "block_uuid": "transformaciondatos", "pipeline_run_id": 23, "pipeline_schedule_id": 1, "pipeline_uuid": "descuento", "hostname": "d79e8dc5d15d", "level": "INFO", "message": "BlockRun 68 (block_uuid: transformaciondatos) completes.", "timestamp": 1739744169.799258, "uuid": "18fe43e44fff43d598bf270d055d6738"}
2025-02-16T22:16:18 {"cpu": 0.0146484375, "cpu_total": 8, "cpu_usage": 0.0018310546875, "memory": 1187.0, "memory_total": 4842.0, "memory_usage": 0.24514663362247005, "pipeline_run_id": 23, "pipeline_schedule_id": 1, "pipeline_uuid": "descuento", "hostname": "d79e8dc5d15d", "level": "INFO", "message": "Pipeline descuento for run 23 in schedule 1 is alive.", "timestamp": 1739744178.769225, "uuid": "fbc38969f4894f7fa8a283c4f2460f2b"}
2025-02-16T22:16:18 {"block_run_id": 69, "block_uuid": "exportaciondatos", "pipeline_run_id": 23, "pipeline_schedule_id": 1, "pipeline_uuid": "descuento", "hostname": "d79e8dc5d15d", "level": "INFO", "message": "Execute PipelineRun 23, BlockRun 69: pipeline descuento block exportaciondatos", "timestamp": 1739744178.844215, "uuid": "13edbb3ca27c4943a383533e193d14c8"}
2025-02-16T22:16:21 {"block_run_id": 69, "block_uuid": "exportaciondatos", "pipeline_run_id": 23, "pipeline_schedule_id": 1, "pipeline_uuid": "descuento", "hostname": "d79e8dc5d15d", "level": "EXCEPTION", "message": "BlockRun 69 (block_uuid: exportaciondatos) failed.", "timestamp": 1739744181.833236, "uuid": "10706da24c624e808a64e115147df6ce", "error": "Traceback (most recent call last):\n  File \"/usr/local/lib/python3.10/site-packages/mage_ai/io/base.py\", line 403, in conn\n    return self._ctx\nAttributeError: 'Postgres' object has no attribute '_ctx'\n\nDuring handling of the above exception, another exception occurred:\n\nTraceback (most recent call last):\n  File \"/usr/local/lib/python3.10/site-packages/mage_ai/data_preparation/executors/block_executor.py\", line 647, in execute\n    result = __execute_with_retry()\n  File \"/usr/local/lib/python3.10/site-packages/mage_ai/shared/retry.py\", line 54, in retry_func\n    raise e\n  File \"/usr/local/lib/python3.10/site-packages/mage_ai/shared/retry.py\", line 38, in retry_func\n    return func(*args, **kwargs)\n  File \"/usr/local/lib/python3.10/site-packages/mage_ai/data_preparation/executors/block_executor.py\", line 621, in __execute_with_retry\n    return self._execute(\n  File \"/usr/local/lib/python3.10/site-packages/mage_ai/data_preparation/executors/block_executor.py\", line 1154, in _execute\n    result = self.block.execute_sync(\n  File \"/usr/local/lib/python3.10/site-packages/mage_ai/data_preparation/models/block/__init__.py\", line 1691, in execute_sync\n    return __execute()\n  File \"/usr/local/lib/python3.10/site-packages/mage_ai/data_preparation/models/block/__init__.py\", line 1668, in __execute\n    raise err\n  File \"/usr/local/lib/python3.10/site-packages/mage_ai/data_preparation/models/block/__init__.py\", line 1570, in __execute\n    output = self.execute_block(\n  File \"/usr/local/lib/python3.10/site-packages/mage_ai/data_preparation/models/block/__init__.py\", line 1910, in execute_block\n    outputs = self._execute_block(\n  File \"/usr/local/lib/python3.10/site-packages/mage_ai/data_preparation/models/block/__init__.py\", line 2073, in _execute_block\n    outputs = self.execute_block_function(\n  File \"/usr/local/lib/python3.10/site-packages/mage_ai/data_preparation/models/block/__init__.py\", line 2169, in execute_block_function\n    output = block_function_updated(*input_vars, **global_vars)\n  File \"<string>\", line 25, in export_data_to_postgres\n  File \"/usr/local/lib/python3.10/site-packages/mage_ai/io/postgres.py\", line 431, in execute\n    with self.conn.cursor() as cur:\n  File \"/usr/local/lib/python3.10/site-packages/mage_ai/io/base.py\", line 405, in conn\n    raise ConnectionError(\nConnectionError: No connection currently open. Open a new connection to access this property.\n", "error_stack": ["  File \"/usr/local/bin/mage\", line 8, in <module>\n    sys.exit(app())\n", "  File \"/usr/local/lib/python3.10/site-packages/typer/main.py\", line 311, in __call__\n    return get_command(self)(*args, **kwargs)\n", "  File \"/usr/local/lib/python3.10/site-packages/click/core.py\", line 1161, in __call__\n    return self.main(*args, **kwargs)\n", "  File \"/usr/local/lib/python3.10/site-packages/typer/core.py\", line 778, in main\n    return _main(\n", "  File \"/usr/local/lib/python3.10/site-packages/typer/core.py\", line 216, in _main\n    rv = self.invoke(ctx)\n", "  File \"/usr/local/lib/python3.10/site-packages/click/core.py\", line 1697, in invoke\n    return _process_result(sub_ctx.command.invoke(sub_ctx))\n", "  File \"/usr/local/lib/python3.10/site-packages/click/core.py\", line 1443, in invoke\n    return ctx.invoke(self.callback, **ctx.params)\n", "  File \"/usr/local/lib/python3.10/site-packages/click/core.py\", line 788, in invoke\n    return __callback(*args, **kwargs)\n", "  File \"/usr/local/lib/python3.10/site-packages/typer/main.py\", line 683, in wrapper\n    return callback(**use_params)  # type: ignore\n", "  File \"/usr/local/lib/python3.10/site-packages/mage_ai/cli/main.py\", line 147, in start\n    start_server(\n", "  File \"/usr/local/lib/python3.10/site-packages/mage_ai/server/server.py\", line 809, in start_server\n    scheduler_manager.start_scheduler()\n", "  File \"/usr/local/lib/python3.10/site-packages/mage_ai/server/scheduler_manager.py\", line 106, in start_scheduler\n    proc.start()\n", "  File \"/usr/local/lib/python3.10/multiprocessing/process.py\", line 121, in start\n    self._popen = self._Popen(self)\n", "  File \"/usr/local/lib/python3.10/multiprocessing/context.py\", line 224, in _Popen\n    return _default_context.get_context().Process._Popen(process_obj)\n", "  File \"/usr/local/lib/python3.10/multiprocessing/context.py\", line 281, in _Popen\n    return Popen(process_obj)\n", "  File \"/usr/local/lib/python3.10/multiprocessing/popen_fork.py\", line 19, in __init__\n    self._launch(process_obj)\n", "  File \"/usr/local/lib/python3.10/multiprocessing/popen_fork.py\", line 71, in _launch\n    code = process_obj._bootstrap(parent_sentinel=child_r)\n", "  File \"/usr/local/lib/python3.10/multiprocessing/process.py\", line 314, in _bootstrap\n    self.run()\n", "  File \"/usr/local/lib/python3.10/multiprocessing/process.py\", line 108, in run\n    self._target(*self._args, **self._kwargs)\n", "  File \"/usr/local/lib/python3.10/site-packages/mage_ai/orchestration/db/process.py\", line 15, in start_session_and_run\n    results = target(*args)\n", "  File \"/usr/local/lib/python3.10/site-packages/mage_ai/server/scheduler_manager.py\", line 58, in run_scheduler\n    LoopTimeTrigger().start()\n", "  File \"/usr/local/lib/python3.10/site-packages/mage_ai/orchestration/triggers/loop_time_trigger.py\", line 14, in start\n    self.run()\n", "  File \"/usr/local/lib/python3.10/site-packages/mage_ai/orchestration/triggers/time_trigger.py\", line 11, in run\n    schedule_all()\n", "  File \"/usr/local/lib/python3.10/site-packages/mage_ai/orchestration/pipeline_scheduler_original.py\", line 1730, in schedule_all\n    PipelineScheduler(r).schedule()\n", "  File \"/usr/local/lib/python3.10/site-packages/mage_ai/orchestration/db/__init__.py\", line 159, in func_with_rollback\n    return func(*args, **kwargs)\n", "  File \"/usr/local/lib/python3.10/site-packages/mage_ai/orchestration/pipeline_scheduler_original.py\", line 333, in schedule\n    self.__schedule_blocks(block_runs)\n", "  File \"/usr/local/lib/python3.10/site-packages/mage_ai/orchestration/pipeline_scheduler_original.py\", line 640, in __schedule_blocks\n    job_manager.add_job(\n", "  File \"/usr/local/lib/python3.10/site-packages/mage_ai/orchestration/job_manager.py\", line 20, in add_job\n    self.queue.enqueue(job_id, target, *args, **kwargs)\n", "  File \"/usr/local/lib/python3.10/site-packages/mage_ai/orchestration/queue/process_queue.py\", line 121, in enqueue\n    self.start_worker_pool()\n", "  File \"/usr/local/lib/python3.10/site-packages/mage_ai/orchestration/queue/process_queue.py\", line 198, in start_worker_pool\n    self.worker_pool_proc.start()\n", "  File \"/usr/local/lib/python3.10/multiprocessing/process.py\", line 121, in start\n    self._popen = self._Popen(self)\n", "  File \"/usr/local/lib/python3.10/multiprocessing/context.py\", line 224, in _Popen\n    return _default_context.get_context().Process._Popen(process_obj)\n", "  File \"/usr/local/lib/python3.10/multiprocessing/context.py\", line 281, in _Popen\n    return Popen(process_obj)\n", "  File \"/usr/local/lib/python3.10/multiprocessing/popen_fork.py\", line 19, in __init__\n    self._launch(process_obj)\n", "  File \"/usr/local/lib/python3.10/multiprocessing/popen_fork.py\", line 71, in _launch\n    code = process_obj._bootstrap(parent_sentinel=child_r)\n", "  File \"/usr/local/lib/python3.10/multiprocessing/process.py\", line 314, in _bootstrap\n    self.run()\n", "  File \"/usr/local/lib/python3.10/multiprocessing/process.py\", line 108, in run\n    self._target(*self._args, **self._kwargs)\n", "  File \"/usr/local/lib/python3.10/site-packages/mage_ai/orchestration/queue/process_queue.py\", line 351, in poll_job_and_execute\n    worker.start()\n", "  File \"/usr/local/lib/python3.10/multiprocessing/process.py\", line 121, in start\n    self._popen = self._Popen(self)\n", "  File \"/usr/local/lib/python3.10/multiprocessing/context.py\", line 224, in _Popen\n    return _default_context.get_context().Process._Popen(process_obj)\n", "  File \"/usr/local/lib/python3.10/multiprocessing/context.py\", line 281, in _Popen\n    return Popen(process_obj)\n", "  File \"/usr/local/lib/python3.10/multiprocessing/popen_fork.py\", line 19, in __init__\n    self._launch(process_obj)\n", "  File \"/usr/local/lib/python3.10/multiprocessing/popen_fork.py\", line 71, in _launch\n    code = process_obj._bootstrap(parent_sentinel=child_r)\n", "  File \"/usr/local/lib/python3.10/multiprocessing/process.py\", line 314, in _bootstrap\n    self.run()\n", "  File \"/usr/local/lib/python3.10/site-packages/newrelic/api/background_task.py\", line 117, in wrapper\n    return wrapped(*args, **kwargs)\n", "  File \"/usr/local/lib/python3.10/site-packages/mage_ai/orchestration/queue/process_queue.py\", line 315, in run\n    start_session_and_run(args[1], *args[2], **args[3])\n", "  File \"/usr/local/lib/python3.10/site-packages/mage_ai/orchestration/db/process.py\", line 15, in start_session_and_run\n    results = target(*args)\n", "  File \"/usr/local/lib/python3.10/site-packages/mage_ai/orchestration/pipeline_scheduler_original.py\", line 1235, in run_block\n    return ExecutorFactory.get_block_executor(\n", "  File \"/usr/local/lib/python3.10/site-packages/mage_ai/data_preparation/executors/block_executor.py\", line 682, in execute\n    on_failure(\n", "  File \"/usr/local/lib/python3.10/site-packages/mage_ai/orchestration/db/__init__.py\", line 159, in func_with_rollback\n    return func(*args, **kwargs)\n", "  File \"/usr/local/lib/python3.10/site-packages/mage_ai/orchestration/pipeline_scheduler_original.py\", line 464, in on_block_failure\n    self.logger.exception(\n", "  File \"/usr/local/lib/python3.10/site-packages/mage_ai/data_preparation/logging/logger.py\", line 30, in exception\n    self.__send_message('exception', message, **kwargs)\n", "  File \"/usr/local/lib/python3.10/site-packages/mage_ai/data_preparation/logging/logger.py\", line 65, in __send_message\n    data['error_stack'] = traceback.format_stack()\n"], "error_stacktrace": "No connection currently open. Open a new connection to access this property."}
Traceback (most recent call last):
  File "/usr/local/lib/python3.10/site-packages/mage_ai/io/base.py", line 403, in conn
    return self._ctx
AttributeError: 'Postgres' object has no attribute '_ctx'

During handling of the above exception, another exception occurred:

Traceback (most recent call last):
  File "/usr/local/lib/python3.10/site-packages/mage_ai/data_preparation/executors/block_executor.py", line 647, in execute
    result = __execute_with_retry()
  File "/usr/local/lib/python3.10/site-packages/mage_ai/shared/retry.py", line 54, in retry_func
    raise e
  File "/usr/local/lib/python3.10/site-packages/mage_ai/shared/retry.py", line 38, in retry_func
    return func(*args, **kwargs)
  File "/usr/local/lib/python3.10/site-packages/mage_ai/data_preparation/executors/block_executor.py", line 621, in __execute_with_retry
    return self._execute(
  File "/usr/local/lib/python3.10/site-packages/mage_ai/data_preparation/executors/block_executor.py", line 1154, in _execute
    result = self.block.execute_sync(
  File "/usr/local/lib/python3.10/site-packages/mage_ai/data_preparation/models/block/__init__.py", line 1691, in execute_sync
    return __execute()
  File "/usr/local/lib/python3.10/site-packages/mage_ai/data_preparation/models/block/__init__.py", line 1668, in __execute
    raise err
  File "/usr/local/lib/python3.10/site-packages/mage_ai/data_preparation/models/block/__init__.py", line 1570, in __execute
    output = self.execute_block(
  File "/usr/local/lib/python3.10/site-packages/mage_ai/data_preparation/models/block/__init__.py", line 1910, in execute_block
    outputs = self._execute_block(
  File "/usr/local/lib/python3.10/site-packages/mage_ai/data_preparation/models/block/__init__.py", line 2073, in _execute_block
    outputs = self.execute_block_function(
  File "/usr/local/lib/python3.10/site-packages/mage_ai/data_preparation/models/block/__init__.py", line 2169, in execute_block_function
    output = block_function_updated(*input_vars, **global_vars)
  File "<string>", line 25, in export_data_to_postgres
  File "/usr/local/lib/python3.10/site-packages/mage_ai/io/postgres.py", line 431, in execute
    with self.conn.cursor() as cur:
  File "/usr/local/lib/python3.10/site-packages/mage_ai/io/base.py", line 405, in conn
    raise ConnectionError(
ConnectionError: No connection currently open. Open a new connection to access this property.
2025-02-16T22:16:28 {"cpu": 0.013671875, "cpu_total": 8, "cpu_usage": 0.001708984375, "memory": 1196.0, "memory_total": 4842.0, "memory_usage": 0.2470053696819496, "pipeline_run_id": 23, "pipeline_schedule_id": 1, "pipeline_uuid": "descuento", "hostname": "d79e8dc5d15d", "level": "INFO", "message": "Pipeline descuento for run 23 in schedule 1 is alive.", "timestamp": 1739744188.635501, "uuid": "0781599ce3ad452d9638b44e12cc1429"}
